<mujoco model="tiago">

  <compiler angle="radian" meshdir="./assets/" autolimits="true" fusestatic="true"/>

  <option integrator="implicitfast"/>

  <asset>
    <material name="black" rgba="0 0 0 1"/>
    <material name="gray10" rgba="0.1 0.1 0.1 1"/>
    <material name="gray70" rgba="0.7 0.7 0.7 1"/>
    <material name="mercury" rgba="0.9 0.9 0.9 1"/>
    <material name="white" rgba="1 1 1 1"/>
    <material name="orange" rgba="1 0.487 0 1"/>

    <mesh file="sensors/sick_tim551.stl"/>
    <mesh file="sensors/srf05.stl"/>
    <mesh file="base/base.stl"/>
    <mesh file="base/base_ring.stl"/>
    <mesh file="objects/antenna.stl"/>
    <mesh file="wheels/wheel.stl"/>
    <mesh file="wheels/caster_1.stl"/>
    <mesh file="wheels/caster_2.stl"/>
    <mesh file="torso/torso_fix.stl"/>
    <mesh file="torso/torso_lift_with_arm.stl"/>
    <mesh file="head/head_1.stl"/>
    <mesh file="head/head_2.stl"/>
    <mesh file="arm/arm_1.stl"/>
    <mesh file="arm/arm_2.stl"/>
    <mesh file="arm/arm_3.stl"/>
    <mesh file="arm/arm_4.stl"/>
    <mesh file="arm/arm_5-wrist-2017.stl"/>
    <mesh file="arm/arm_6-wrist-2017.stl"/>
    <mesh file="gripper/gripper_link.stl"/>
    <mesh name="gripper_right_finger_link" file="gripper/gripper_finger_link.stl" scale="-1 -1 1"/>
    <mesh name="gripper_left_finger_link" file="gripper/gripper_finger_link.stl"/>
  </asset>

  <default>
    <geom contype="0" conaffinity="1" group="1" type="mesh" mass="0"/>
    <joint axis="0 0 1"/>
    <default class="arm">
      <geom contype="1" conaffinity="1"/>
      <joint frictionloss="1"/>
    </default>
    <default class="wheel">
      <geom condim="6"/>
    </default>
  </default>

  <worldbody>
    <body name="base_link" pos="2.0 2.0 0">
      <joint name="odom_vel_lin_x_joint" type="slide" axis="1.0 0.0 0.0"/>
			<joint name="odom_vel_lin_y_joint" type="slide" axis="0.0 1.0 0.0"/>
			<joint name="odom_vel_ang_z_joint" type="hinge" axis="0.0 0.0 1.0"/>
      <body name="laser_mount" pos="0.202 0 0.4" euler="0 0 0">
        <body name="laser_body" euler="1.5707 0 0">
          <site name="laser_site_000" pos="0 0 0"/>
          <site name="laser_site_001" pos="0 0 0" quat="0.999998 0 0.0021815 0"/>
          <site name="laser_site_002" pos="0 0 0" quat="0.99999 0 0.00436299 0"/>
          <site name="laser_site_003" pos="0 0 0" quat="0.999979 0 0.00654445 0"/>
          <site name="laser_site_004" pos="0 0 0" quat="0.999962 0 0.00872589 0"/>
          <site name="laser_site_005" pos="0 0 0" quat="0.999941 0 0.0109073 0"/>
          <site name="laser_site_006" pos="0 0 0" quat="0.999914 0 0.0130886 0"/>
          <site name="laser_site_007" pos="0 0 0" quat="0.999883 0 0.0152699 0"/>
          <site name="laser_site_008" pos="0 0 0" quat="0.999848 0 0.0174511 0"/>
          <site name="laser_site_009" pos="0 0 0" quat="0.999807 0 0.0196322 0"/>
          <site name="laser_site_010" pos="0 0 0" quat="0.999762 0 0.0218133 0"/>
          <site name="laser_site_011" pos="0 0 0" quat="0.999712 0 0.0239942 0"/>
          <site name="laser_site_012" pos="0 0 0" quat="0.999657 0 0.026175 0"/>
          <site name="laser_site_013" pos="0 0 0" quat="0.999598 0 0.0283557 0"/>
          <site name="laser_site_014" pos="0 0 0" quat="0.999534 0 0.0305363 0"/>
          <site name="laser_site_015" pos="0 0 0" quat="0.999465 0 0.0327167 0"/>
          <site name="laser_site_016" pos="0 0 0" quat="0.999391 0 0.0348969 0"/>
          <site name="laser_site_017" pos="0 0 0" quat="0.999312 0 0.037077 0"/>
          <site name="laser_site_018" pos="0 0 0" quat="0.999229 0 0.0392569 0"/>
          <site name="laser_site_019" pos="0 0 0" quat="0.999141 0 0.0414366 0"/>
          <site name="laser_site_020" pos="0 0 0" quat="0.999048 0 0.0436162 0"/>
          <site name="laser_site_021" pos="0 0 0" quat="0.998951 0 0.0457955 0"/>
          <site name="laser_site_022" pos="0 0 0" quat="0.998849 0 0.0479746 0"/>
          <site name="laser_site_023" pos="0 0 0" quat="0.998742 0 0.0501535 0"/>
          <site name="laser_site_024" pos="0 0 0" quat="0.99863 0 0.0523321 0"/>
          <site name="laser_site_025" pos="0 0 0" quat="0.998513 0 0.0545105 0"/>
          <site name="laser_site_026" pos="0 0 0" quat="0.998392 0 0.0566886 0"/>
          <site name="laser_site_027" pos="0 0 0" quat="0.998266 0 0.0588664 0"/>
          <site name="laser_site_028" pos="0 0 0" quat="0.998135 0 0.061044 0"/>
          <site name="laser_site_029" pos="0 0 0" quat="0.998 0 0.0632213 0"/>
          <site name="laser_site_030" pos="0 0 0" quat="0.997859 0 0.0653983 0"/>
          <site name="laser_site_031" pos="0 0 0" quat="0.997714 0 0.067575 0"/>
          <site name="laser_site_032" pos="0 0 0" quat="0.997564 0 0.0697513 0"/>
          <site name="laser_site_033" pos="0 0 0" quat="0.99741 0 0.0719273 0"/>
          <site name="laser_site_034" pos="0 0 0" quat="0.997251 0 0.074103 0"/>
          <site name="laser_site_035" pos="0 0 0" quat="0.997087 0 0.0762783 0"/>
          <site name="laser_site_036" pos="0 0 0" quat="0.996918 0 0.0784533 0"/>
          <site name="laser_site_037" pos="0 0 0" quat="0.996744 0 0.0806279 0"/>
          <site name="laser_site_038" pos="0 0 0" quat="0.996566 0 0.0828021 0"/>
          <site name="laser_site_039" pos="0 0 0" quat="0.996383 0 0.0849759 0"/>
          <site name="laser_site_040" pos="0 0 0" quat="0.996195 0 0.0871493 0"/>
          <site name="laser_site_041" pos="0 0 0" quat="0.996003 0 0.0893223 0"/>
          <site name="laser_site_042" pos="0 0 0" quat="0.995806 0 0.0914949 0"/>
          <site name="laser_site_043" pos="0 0 0" quat="0.995604 0 0.093667 0"/>
          <site name="laser_site_044" pos="0 0 0" quat="0.995397 0 0.0958387 0"/>
          <site name="laser_site_045" pos="0 0 0" quat="0.995185 0 0.0980099 0"/>
          <site name="laser_site_046" pos="0 0 0" quat="0.994969 0 0.100181 0"/>
          <site name="laser_site_047" pos="0 0 0" quat="0.994748 0 0.102351 0"/>
          <site name="laser_site_048" pos="0 0 0" quat="0.994523 0 0.104521 0"/>
          <site name="laser_site_049" pos="0 0 0" quat="0.994292 0 0.10669 0"/>
          <site name="laser_site_050" pos="0 0 0" quat="0.994057 0 0.108859 0"/>
          <site name="laser_site_051" pos="0 0 0" quat="0.993817 0 0.111027 0"/>
          <site name="laser_site_052" pos="0 0 0" quat="0.993573 0 0.113195 0"/>
          <site name="laser_site_053" pos="0 0 0" quat="0.993324 0 0.115362 0"/>
          <site name="laser_site_054" pos="0 0 0" quat="0.993069 0 0.117529 0"/>
          <site name="laser_site_055" pos="0 0 0" quat="0.992811 0 0.119695 0"/>
          <site name="laser_site_056" pos="0 0 0" quat="0.992547 0 0.12186 0"/>
          <site name="laser_site_057" pos="0 0 0" quat="0.992279 0 0.124025 0"/>
          <site name="laser_site_058" pos="0 0 0" quat="0.992006 0 0.12619 0"/>
          <site name="laser_site_059" pos="0 0 0" quat="0.991728 0 0.128353 0"/>
          <site name="laser_site_060" pos="0 0 0" quat="0.991446 0 0.130517 0"/>
          <site name="laser_site_061" pos="0 0 0" quat="0.991159 0 0.132679 0"/>
          <site name="laser_site_062" pos="0 0 0" quat="0.990867 0 0.134841 0"/>
          <site name="laser_site_063" pos="0 0 0" quat="0.990571 0 0.137002 0"/>
          <site name="laser_site_064" pos="0 0 0" quat="0.99027 0 0.139163 0"/>
          <site name="laser_site_065" pos="0 0 0" quat="0.989964 0 0.141323 0"/>
          <site name="laser_site_066" pos="0 0 0" quat="0.989653 0 0.143482 0"/>
          <site name="laser_site_067" pos="0 0 0" quat="0.989338 0 0.145641 0"/>
          <site name="laser_site_068" pos="0 0 0" quat="0.989017 0 0.147799 0"/>
          <site name="laser_site_069" pos="0 0 0" quat="0.988693 0 0.149956 0"/>
          <site name="laser_site_070" pos="0 0 0" quat="0.988363 0 0.152112 0"/>
          <site name="laser_site_071" pos="0 0 0" quat="0.988029 0 0.154268 0"/>
          <site name="laser_site_072" pos="0 0 0" quat="0.98769 0 0.156423 0"/>
          <site name="laser_site_073" pos="0 0 0" quat="0.987347 0 0.158577 0"/>
          <site name="laser_site_074" pos="0 0 0" quat="0.986998 0 0.160731 0"/>
          <site name="laser_site_075" pos="0 0 0" quat="0.986645 0 0.162884 0"/>
          <site name="laser_site_076" pos="0 0 0" quat="0.986288 0 0.165035 0"/>
          <site name="laser_site_077" pos="0 0 0" quat="0.985925 0 0.167187 0"/>
          <site name="laser_site_078" pos="0 0 0" quat="0.985558 0 0.169337 0"/>
          <site name="laser_site_079" pos="0 0 0" quat="0.985186 0 0.171487 0"/>
          <site name="laser_site_080" pos="0 0 0" quat="0.98481 0 0.173635 0"/>
          <site name="laser_site_081" pos="0 0 0" quat="0.984429 0 0.175783 0"/>
          <site name="laser_site_082" pos="0 0 0" quat="0.984043 0 0.177931 0"/>
          <site name="laser_site_083" pos="0 0 0" quat="0.983653 0 0.180077 0"/>
          <site name="laser_site_084" pos="0 0 0" quat="0.983257 0 0.182222 0"/>
          <site name="laser_site_085" pos="0 0 0" quat="0.982858 0 0.184367 0"/>
          <site name="laser_site_086" pos="0 0 0" quat="0.982453 0 0.18651 0"/>
          <site name="laser_site_087" pos="0 0 0" quat="0.982044 0 0.188653 0"/>
          <site name="laser_site_088" pos="0 0 0" quat="0.98163 0 0.190795 0"/>
          <site name="laser_site_089" pos="0 0 0" quat="0.981211 0 0.192936 0"/>
          <site name="laser_site_090" pos="0 0 0" quat="0.980788 0 0.195076 0"/>
          <site name="laser_site_091" pos="0 0 0" quat="0.98036 0 0.197215 0"/>
          <site name="laser_site_092" pos="0 0 0" quat="0.979928 0 0.199353 0"/>
          <site name="laser_site_093" pos="0 0 0" quat="0.97949 0 0.201491 0"/>
          <site name="laser_site_094" pos="0 0 0" quat="0.979049 0 0.203627 0"/>
          <site name="laser_site_095" pos="0 0 0" quat="0.978602 0 0.205762 0"/>
          <site name="laser_site_096" pos="0 0 0" quat="0.978151 0 0.207897 0"/>
          <site name="laser_site_097" pos="0 0 0" quat="0.977695 0 0.21003 0"/>
          <site name="laser_site_098" pos="0 0 0" quat="0.977234 0 0.212162 0"/>
          <site name="laser_site_099" pos="0 0 0" quat="0.976769 0 0.214294 0"/>
          <site name="laser_site_100" pos="0 0 0" quat="0.9763 0 0.216424 0"/>
          <site name="laser_site_101" pos="0 0 0" quat="0.975825 0 0.218553 0"/>
          <site name="laser_site_102" pos="0 0 0" quat="0.975346 0 0.220681 0"/>
          <site name="laser_site_103" pos="0 0 0" quat="0.974862 0 0.222809 0"/>
          <site name="laser_site_104" pos="0 0 0" quat="0.974374 0 0.224935 0"/>
          <site name="laser_site_105" pos="0 0 0" quat="0.973881 0 0.22706 0"/>
          <site name="laser_site_106" pos="0 0 0" quat="0.973383 0 0.229184 0"/>
          <site name="laser_site_107" pos="0 0 0" quat="0.972881 0 0.231307 0"/>
          <site name="laser_site_108" pos="0 0 0" quat="0.972374 0 0.233428 0"/>
          <site name="laser_site_109" pos="0 0 0" quat="0.971862 0 0.235549 0"/>
          <site name="laser_site_110" pos="0 0 0" quat="0.971346 0 0.237669 0"/>
          <site name="laser_site_111" pos="0 0 0" quat="0.970826 0 0.239787 0"/>
          <site name="laser_site_112" pos="0 0 0" quat="0.9703 0 0.241904 0"/>
          <site name="laser_site_113" pos="0 0 0" quat="0.96977 0 0.24402 0"/>
          <site name="laser_site_114" pos="0 0 0" quat="0.969235 0 0.246135 0"/>
          <site name="laser_site_115" pos="0 0 0" quat="0.968696 0 0.248249 0"/>
          <site name="laser_site_116" pos="0 0 0" quat="0.968152 0 0.250362 0"/>
          <site name="laser_site_117" pos="0 0 0" quat="0.967604 0 0.252473 0"/>
          <site name="laser_site_118" pos="0 0 0" quat="0.967051 0 0.254584 0"/>
          <site name="laser_site_119" pos="0 0 0" quat="0.966493 0 0.256693 0"/>
          <site name="laser_site_120" pos="0 0 0" quat="0.965931 0 0.2588 0"/>
          <site name="laser_site_121" pos="0 0 0" quat="0.965364 0 0.260907 0"/>
          <site name="laser_site_122" pos="0 0 0" quat="0.964793 0 0.263012 0"/>
          <site name="laser_site_123" pos="0 0 0" quat="0.964216 0 0.265116 0"/>
          <site name="laser_site_124" pos="0 0 0" quat="0.963636 0 0.267219 0"/>
          <site name="laser_site_125" pos="0 0 0" quat="0.963051 0 0.269321 0"/>
          <site name="laser_site_126" pos="0 0 0" quat="0.962461 0 0.271421 0"/>
          <site name="laser_site_127" pos="0 0 0" quat="0.961866 0 0.27352 0"/>
          <site name="laser_site_128" pos="0 0 0" quat="0.961267 0 0.275617 0"/>
          <site name="laser_site_129" pos="0 0 0" quat="0.960664 0 0.277714 0"/>
          <site name="laser_site_130" pos="0 0 0" quat="0.960056 0 0.279809 0"/>
          <site name="laser_site_131" pos="0 0 0" quat="0.959443 0 0.281903 0"/>
          <site name="laser_site_132" pos="0 0 0" quat="0.958826 0 0.283995 0"/>
          <site name="laser_site_133" pos="0 0 0" quat="0.958204 0 0.286086 0"/>
          <site name="laser_site_134" pos="0 0 0" quat="0.957578 0 0.288176 0"/>
          <site name="laser_site_135" pos="0 0 0" quat="0.956947 0 0.290264 0"/>
          <site name="laser_site_136" pos="0 0 0" quat="0.956311 0 0.292351 0"/>
          <site name="laser_site_137" pos="0 0 0" quat="0.955671 0 0.294436 0"/>
          <site name="laser_site_138" pos="0 0 0" quat="0.955027 0 0.29652 0"/>
          <site name="laser_site_139" pos="0 0 0" quat="0.954377 0 0.298603 0"/>
          <site name="laser_site_140" pos="0 0 0" quat="0.953724 0 0.300684 0"/>
          <site name="laser_site_141" pos="0 0 0" quat="0.953066 0 0.302764 0"/>
          <site name="laser_site_142" pos="0 0 0" quat="0.952403 0 0.304842 0"/>
          <site name="laser_site_143" pos="0 0 0" quat="0.951736 0 0.306919 0"/>
          <site name="laser_site_144" pos="0 0 0" quat="0.951064 0 0.308995 0"/>
          <site name="laser_site_145" pos="0 0 0" quat="0.950387 0 0.311069 0"/>
          <site name="laser_site_146" pos="0 0 0" quat="0.949707 0 0.313141 0"/>
          <site name="laser_site_147" pos="0 0 0" quat="0.949021 0 0.315212 0"/>
          <site name="laser_site_148" pos="0 0 0" quat="0.948331 0 0.317282 0"/>
          <site name="laser_site_149" pos="0 0 0" quat="0.947637 0 0.31935 0"/>
          <site name="laser_site_150" pos="0 0 0" quat="0.946938 0 0.321417 0"/>
          <site name="laser_site_151" pos="0 0 0" quat="0.946234 0 0.323481 0"/>
          <site name="laser_site_152" pos="0 0 0" quat="0.945527 0 0.325545 0"/>
          <site name="laser_site_153" pos="0 0 0" quat="0.944814 0 0.327607 0"/>
          <site name="laser_site_154" pos="0 0 0" quat="0.944097 0 0.329667 0"/>
          <site name="laser_site_155" pos="0 0 0" quat="0.943376 0 0.331726 0"/>
          <site name="laser_site_156" pos="0 0 0" quat="0.94265 0 0.333783 0"/>
          <site name="laser_site_157" pos="0 0 0" quat="0.94192 0 0.335839 0"/>
          <site name="laser_site_158" pos="0 0 0" quat="0.941185 0 0.337893 0"/>
          <site name="laser_site_159" pos="0 0 0" quat="0.940445 0 0.339945 0"/>
          <site name="laser_site_160" pos="0 0 0" quat="0.939701 0 0.341996 0"/>
          <site name="laser_site_161" pos="0 0 0" quat="0.938953 0 0.344045 0"/>
          <site name="laser_site_162" pos="0 0 0" quat="0.9382 0 0.346093 0"/>
          <site name="laser_site_163" pos="0 0 0" quat="0.937443 0 0.348138 0"/>
          <site name="laser_site_164" pos="0 0 0" quat="0.936681 0 0.350183 0"/>
          <site name="laser_site_165" pos="0 0 0" quat="0.935915 0 0.352225 0"/>
          <site name="laser_site_166" pos="0 0 0" quat="0.935145 0 0.354266 0"/>
          <site name="laser_site_167" pos="0 0 0" quat="0.93437 0 0.356305 0"/>
          <site name="laser_site_168" pos="0 0 0" quat="0.93359 0 0.358343 0"/>
          <site name="laser_site_169" pos="0 0 0" quat="0.932806 0 0.360378 0"/>
          <site name="laser_site_170" pos="0 0 0" quat="0.932018 0 0.362412 0"/>
          <site name="laser_site_171" pos="0 0 0" quat="0.931225 0 0.364445 0"/>
          <site name="laser_site_172" pos="0 0 0" quat="0.930428 0 0.366475 0"/>
          <site name="laser_site_173" pos="0 0 0" quat="0.929626 0 0.368504 0"/>
          <site name="laser_site_174" pos="0 0 0" quat="0.92882 0 0.370531 0"/>
          <site name="laser_site_175" pos="0 0 0" quat="0.928009 0 0.372557 0"/>
          <site name="laser_site_176" pos="0 0 0" quat="0.927195 0 0.37458 0"/>
          <site name="laser_site_177" pos="0 0 0" quat="0.926375 0 0.376602 0"/>
          <site name="laser_site_178" pos="0 0 0" quat="0.925551 0 0.378622 0"/>
          <site name="laser_site_179" pos="0 0 0" quat="0.924723 0 0.38064 0"/>
          <site name="laser_site_180" pos="0 0 0" quat="0.923891 0 0.382657 0"/>
          <site name="laser_site_181" pos="0 0 0" quat="0.923054 0 0.384671 0"/>
          <site name="laser_site_182" pos="0 0 0" quat="0.922212 0 0.386684 0"/>
          <site name="laser_site_183" pos="0 0 0" quat="0.921367 0 0.388695 0"/>
          <site name="laser_site_184" pos="0 0 0" quat="0.920516 0 0.390704 0"/>
          <site name="laser_site_185" pos="0 0 0" quat="0.919662 0 0.392711 0"/>
          <site name="laser_site_186" pos="0 0 0" quat="0.918803 0 0.394716 0"/>
          <site name="laser_site_187" pos="0 0 0" quat="0.91794 0 0.39672 0"/>
          <site name="laser_site_188" pos="0 0 0" quat="0.917072 0 0.398721 0"/>
          <site name="laser_site_189" pos="0 0 0" quat="0.9162 0 0.400721 0"/>
          <site name="laser_site_190" pos="0 0 0" quat="0.915324 0 0.402719 0"/>
          <site name="laser_site_191" pos="0 0 0" quat="0.914443 0 0.404714 0"/>
          <site name="laser_site_192" pos="0 0 0" quat="0.913558 0 0.406708 0"/>
          <site name="laser_site_193" pos="0 0 0" quat="0.912669 0 0.4087 0"/>
          <site name="laser_site_194" pos="0 0 0" quat="0.911775 0 0.41069 0"/>
          <site name="laser_site_195" pos="0 0 0" quat="0.910877 0 0.412678 0"/>
          <site name="laser_site_196" pos="0 0 0" quat="0.909974 0 0.414664 0"/>
          <site name="laser_site_197" pos="0 0 0" quat="0.909068 0 0.416649 0"/>
          <site name="laser_site_198" pos="0 0 0" quat="0.908157 0 0.418631 0"/>
          <site name="laser_site_199" pos="0 0 0" quat="0.907241 0 0.420611 0"/>
          <site name="laser_site_200" pos="0 0 0" quat="0.906321 0 0.422589 0"/>
          <site name="laser_site_201" pos="0 0 0" quat="0.905397 0 0.424565 0"/>
          <site name="laser_site_202" pos="0 0 0" quat="0.904469 0 0.426539 0"/>
          <site name="laser_site_203" pos="0 0 0" quat="0.903536 0 0.428511 0"/>
          <site name="laser_site_204" pos="0 0 0" quat="0.902599 0 0.430481 0"/>
          <site name="laser_site_205" pos="0 0 0" quat="0.901658 0 0.432449 0"/>
          <site name="laser_site_206" pos="0 0 0" quat="0.900713 0 0.434415 0"/>
          <site name="laser_site_207" pos="0 0 0" quat="0.899763 0 0.436379 0"/>
          <site name="laser_site_208" pos="0 0 0" quat="0.898809 0 0.438341 0"/>
          <site name="laser_site_209" pos="0 0 0" quat="0.89785 0 0.440301 0"/>
          <site name="laser_site_210" pos="0 0 0" quat="0.896888 0 0.442258 0"/>
          <site name="laser_site_211" pos="0 0 0" quat="0.895921 0 0.444214 0"/>
          <site name="laser_site_212" pos="0 0 0" quat="0.89495 0 0.446167 0"/>
          <site name="laser_site_213" pos="0 0 0" quat="0.893974 0 0.448118 0"/>
          <site name="laser_site_214" pos="0 0 0" quat="0.892995 0 0.450068 0"/>
          <site name="laser_site_215" pos="0 0 0" quat="0.892011 0 0.452015 0"/>
          <site name="laser_site_216" pos="0 0 0" quat="0.891022 0 0.453959 0"/>
          <site name="laser_site_217" pos="0 0 0" quat="0.89003 0 0.455902 0"/>
          <site name="laser_site_218" pos="0 0 0" quat="0.889033 0 0.457843 0"/>
          <site name="laser_site_219" pos="0 0 0" quat="0.888032 0 0.459781 0"/>
          <site name="laser_site_220" pos="0 0 0" quat="0.887027 0 0.461717 0"/>
          <site name="laser_site_221" pos="0 0 0" quat="0.886018 0 0.463651 0"/>
          <site name="laser_site_222" pos="0 0 0" quat="0.885004 0 0.465583 0"/>
          <site name="laser_site_223" pos="0 0 0" quat="0.883987 0 0.467512 0"/>
          <site name="laser_site_224" pos="0 0 0" quat="0.882965 0 0.46944 0"/>
          <site name="laser_site_225" pos="0 0 0" quat="0.881938 0 0.471365 0"/>
          <site name="laser_site_226" pos="0 0 0" quat="0.880908 0 0.473288 0"/>
          <site name="laser_site_227" pos="0 0 0" quat="0.879873 0 0.475208 0"/>
          <site name="laser_site_228" pos="0 0 0" quat="0.878835 0 0.477126 0"/>
          <site name="laser_site_229" pos="0 0 0" quat="0.877792 0 0.479042 0"/>
          <site name="laser_site_230" pos="0 0 0" quat="0.876745 0 0.480956 0"/>
          <site name="laser_site_231" pos="0 0 0" quat="0.875693 0 0.482868 0"/>
          <site name="laser_site_232" pos="0 0 0" quat="0.874638 0 0.484777 0"/>
          <site name="laser_site_233" pos="0 0 0" quat="0.873578 0 0.486684 0"/>
          <site name="laser_site_234" pos="0 0 0" quat="0.872514 0 0.488588 0"/>
          <site name="laser_site_235" pos="0 0 0" quat="0.871447 0 0.49049 0"/>
          <site name="laser_site_236" pos="0 0 0" quat="0.870374 0 0.49239 0"/>
          <site name="laser_site_237" pos="0 0 0" quat="0.869298 0 0.494288 0"/>
          <site name="laser_site_238" pos="0 0 0" quat="0.868218 0 0.496183 0"/>
          <site name="laser_site_239" pos="0 0 0" quat="0.867133 0 0.498076 0"/>
          <site name="laser_site_240" pos="0 0 0" quat="0.866045 0 0.499966 0"/>
          <site name="laser_site_241" pos="0 0 0" quat="0.864952 0 0.501855 0"/>
          <site name="laser_site_242" pos="0 0 0" quat="0.863855 0 0.50374 0"/>
          <site name="laser_site_243" pos="0 0 0" quat="0.862754 0 0.505624 0"/>
          <site name="laser_site_244" pos="0 0 0" quat="0.861649 0 0.507504 0"/>
          <site name="laser_site_245" pos="0 0 0" quat="0.86054 0 0.509383 0"/>
          <site name="laser_site_246" pos="0 0 0" quat="0.859427 0 0.511259 0"/>
          <site name="laser_site_247" pos="0 0 0" quat="0.858309 0 0.513133 0"/>
          <site name="laser_site_248" pos="0 0 0" quat="0.857188 0 0.515004 0"/>
          <site name="laser_site_249" pos="0 0 0" quat="0.856062 0 0.516872 0"/>
          <site name="laser_site_250" pos="0 0 0" quat="0.854933 0 0.518739 0"/>
          <site name="laser_site_251" pos="0 0 0" quat="0.853799 0 0.520603 0"/>
          <site name="laser_site_252" pos="0 0 0" quat="0.852661 0 0.522464 0"/>
          <site name="laser_site_253" pos="0 0 0" quat="0.85152 0 0.524323 0"/>
          <site name="laser_site_254" pos="0 0 0" quat="0.850374 0 0.526179 0"/>
          <site name="laser_site_255" pos="0 0 0" quat="0.849224 0 0.528033 0"/>
          <site name="laser_site_256" pos="0 0 0" quat="0.84807 0 0.529884 0"/>
          <site name="laser_site_257" pos="0 0 0" quat="0.846912 0 0.531733 0"/>
          <site name="laser_site_258" pos="0 0 0" quat="0.84575 0 0.533579 0"/>
          <site name="laser_site_259" pos="0 0 0" quat="0.844584 0 0.535423 0"/>
          <site name="laser_site_260" pos="0 0 0" quat="0.843414 0 0.537264 0"/>
          <site name="laser_site_261" pos="0 0 0" quat="0.84224 0 0.539103 0"/>
          <site name="laser_site_262" pos="0 0 0" quat="0.841062 0 0.540939 0"/>
          <site name="laser_site_263" pos="0 0 0" quat="0.83988 0 0.542772 0"/>
          <site name="laser_site_264" pos="0 0 0" quat="0.838694 0 0.544603 0"/>
          <site name="laser_site_265" pos="0 0 0" quat="0.837504 0 0.546432 0"/>
          <site name="laser_site_266" pos="0 0 0" quat="0.83631 0 0.548257 0"/>
          <site name="laser_site_267" pos="0 0 0" quat="0.835112 0 0.55008 0"/>
          <site name="laser_site_268" pos="0 0 0" quat="0.83391 0 0.551901 0"/>
          <site name="laser_site_269" pos="0 0 0" quat="0.832704 0 0.553719 0"/>
          <site name="laser_site_270" pos="0 0 0" quat="0.831494 0 0.555534 0"/>
          <site name="laser_site_271" pos="0 0 0" quat="0.83028 0 0.557347 0"/>
          <site name="laser_site_272" pos="0 0 0" quat="0.829062 0 0.559156 0"/>
          <site name="laser_site_273" pos="0 0 0" quat="0.82784 0 0.560964 0"/>
          <site name="laser_site_274" pos="0 0 0" quat="0.826615 0 0.562768 0"/>
          <site name="laser_site_275" pos="0 0 0" quat="0.825385 0 0.56457 0"/>
          <site name="laser_site_276" pos="0 0 0" quat="0.824151 0 0.566369 0"/>
          <site name="laser_site_277" pos="0 0 0" quat="0.822914 0 0.568166 0"/>
          <site name="laser_site_278" pos="0 0 0" quat="0.821673 0 0.56996 0"/>
          <site name="laser_site_279" pos="0 0 0" quat="0.820427 0 0.571751 0"/>
          <site name="laser_site_280" pos="0 0 0" quat="0.819178 0 0.573539 0"/>
          <site name="laser_site_281" pos="0 0 0" quat="0.817925 0 0.575325 0"/>
          <site name="laser_site_282" pos="0 0 0" quat="0.816668 0 0.577108 0"/>
          <site name="laser_site_283" pos="0 0 0" quat="0.815407 0 0.578888 0"/>
          <site name="laser_site_284" pos="0 0 0" quat="0.814142 0 0.580666 0"/>
          <site name="laser_site_285" pos="0 0 0" quat="0.812874 0 0.58244 0"/>
          <site name="laser_site_286" pos="0 0 0" quat="0.811601 0 0.584212 0"/>
          <site name="laser_site_287" pos="0 0 0" quat="0.810325 0 0.585981 0"/>
          <site name="laser_site_288" pos="0 0 0" quat="0.809044 0 0.587748 0"/>
          <site name="laser_site_289" pos="0 0 0" quat="0.80776 0 0.589511 0"/>
          <site name="laser_site_290" pos="0 0 0" quat="0.806472 0 0.591272 0"/>
          <site name="laser_site_291" pos="0 0 0" quat="0.805181 0 0.59303 0"/>
          <site name="laser_site_292" pos="0 0 0" quat="0.803885 0 0.594785 0"/>
          <site name="laser_site_293" pos="0 0 0" quat="0.802585 0 0.596537 0"/>
          <site name="laser_site_294" pos="0 0 0" quat="0.801282 0 0.598287 0"/>
          <site name="laser_site_295" pos="0 0 0" quat="0.799975 0 0.600033 0"/>
          <site name="laser_site_296" pos="0 0 0" quat="0.798664 0 0.601777 0"/>
          <site name="laser_site_297" pos="0 0 0" quat="0.79735 0 0.603518 0"/>
          <site name="laser_site_298" pos="0 0 0" quat="0.796031 0 0.605256 0"/>
          <site name="laser_site_299" pos="0 0 0" quat="0.794709 0 0.606991 0"/>
          <site name="laser_site_300" pos="0 0 0" quat="0.793383 0 0.608723 0"/>
          <site name="laser_site_301" pos="0 0 0" quat="0.792053 0 0.610452 0"/>
          <site name="laser_site_302" pos="0 0 0" quat="0.790719 0 0.612179 0"/>
          <site name="laser_site_303" pos="0 0 0" quat="0.789382 0 0.613902 0"/>
          <site name="laser_site_304" pos="0 0 0" quat="0.788041 0 0.615623 0"/>
          <site name="laser_site_305" pos="0 0 0" quat="0.786696 0 0.61734 0"/>
          <site name="laser_site_306" pos="0 0 0" quat="0.785348 0 0.619055 0"/>
          <site name="laser_site_307" pos="0 0 0" quat="0.783995 0 0.620767 0"/>
          <site name="laser_site_308" pos="0 0 0" quat="0.782639 0 0.622476 0"/>
          <site name="laser_site_309" pos="0 0 0" quat="0.781279 0 0.624182 0"/>
          <site name="laser_site_310" pos="0 0 0" quat="0.779916 0 0.625884 0"/>
          <site name="laser_site_311" pos="0 0 0" quat="0.778549 0 0.627584 0"/>
          <site name="laser_site_312" pos="0 0 0" quat="0.777178 0 0.629281 0"/>
          <site name="laser_site_313" pos="0 0 0" quat="0.775803 0 0.630975 0"/>
          <site name="laser_site_314" pos="0 0 0" quat="0.774425 0 0.632666 0"/>
          <site name="laser_site_315" pos="0 0 0" quat="0.773043 0 0.634354 0"/>
          <site name="laser_site_316" pos="0 0 0" quat="0.771657 0 0.636039 0"/>
          <site name="laser_site_317" pos="0 0 0" quat="0.770268 0 0.637721 0"/>
          <site name="laser_site_318" pos="0 0 0" quat="0.768875 0 0.639399 0"/>
          <site name="laser_site_319" pos="0 0 0" quat="0.767478 0 0.641075 0"/>
          <site name="laser_site_320" pos="0 0 0" quat="0.766078 0 0.642748 0"/>
          <site name="laser_site_321" pos="0 0 0" quat="0.764674 0 0.644418 0"/>
          <site name="laser_site_322" pos="0 0 0" quat="0.763266 0 0.646084 0"/>
          <site name="laser_site_323" pos="0 0 0" quat="0.761855 0 0.647748 0"/>
          <site name="laser_site_324" pos="0 0 0" quat="0.76044 0 0.649408 0"/>
          <site name="laser_site_325" pos="0 0 0" quat="0.759021 0 0.651066 0"/>
          <site name="laser_site_326" pos="0 0 0" quat="0.757599 0 0.65272 0"/>
          <site name="laser_site_327" pos="0 0 0" quat="0.756174 0 0.654371 0"/>
          <site name="laser_site_328" pos="0 0 0" quat="0.754744 0 0.656019 0"/>
          <site name="laser_site_329" pos="0 0 0" quat="0.753311 0 0.657664 0"/>
          <site name="laser_site_330" pos="0 0 0" quat="0.751875 0 0.659306 0"/>
          <site name="laser_site_331" pos="0 0 0" quat="0.750435 0 0.660944 0"/>
          <site name="laser_site_332" pos="0 0 0" quat="0.748991 0 0.66258 0"/>
          <site name="laser_site_333" pos="0 0 0" quat="0.747544 0 0.664212 0"/>
          <site name="laser_site_334" pos="0 0 0" quat="0.746093 0 0.665841 0"/>
          <site name="laser_site_335" pos="0 0 0" quat="0.744639 0 0.667467 0"/>
          <site name="laser_site_336" pos="0 0 0" quat="0.743181 0 0.66909 0"/>
          <site name="laser_site_337" pos="0 0 0" quat="0.74172 0 0.67071 0"/>
          <site name="laser_site_338" pos="0 0 0" quat="0.740255 0 0.672326 0"/>
          <site name="laser_site_339" pos="0 0 0" quat="0.738786 0 0.67394 0"/>
          <site name="laser_site_340" pos="0 0 0" quat="0.737314 0 0.67555 0"/>
          <site name="laser_site_341" pos="0 0 0" quat="0.735839 0 0.677157 0"/>
          <site name="laser_site_342" pos="0 0 0" quat="0.73436 0 0.67876 0"/>
          <site name="laser_site_343" pos="0 0 0" quat="0.732878 0 0.680361 0"/>
          <site name="laser_site_344" pos="0 0 0" quat="0.731392 0 0.681958 0"/>
          <site name="laser_site_345" pos="0 0 0" quat="0.729902 0 0.683552 0"/>
          <site name="laser_site_346" pos="0 0 0" quat="0.728409 0 0.685142 0"/>
          <site name="laser_site_347" pos="0 0 0" quat="0.726913 0 0.68673 0"/>
          <site name="laser_site_348" pos="0 0 0" quat="0.725413 0 0.688314 0"/>
          <site name="laser_site_349" pos="0 0 0" quat="0.72391 0 0.689895 0"/>
          <site name="laser_site_350" pos="0 0 0" quat="0.722403 0 0.691472 0"/>
          <site name="laser_site_351" pos="0 0 0" quat="0.720893 0 0.693046 0"/>
          <site name="laser_site_352" pos="0 0 0" quat="0.719379 0 0.694617 0"/>
          <site name="laser_site_353" pos="0 0 0" quat="0.717862 0 0.696185 0"/>
          <site name="laser_site_354" pos="0 0 0" quat="0.716342 0 0.697749 0"/>
          <site name="laser_site_355" pos="0 0 0" quat="0.714818 0 0.699311 0"/>
          <site name="laser_site_356" pos="0 0 0" quat="0.713291 0 0.700868 0"/>
          <site name="laser_site_357" pos="0 0 0" quat="0.71176 0 0.702423 0"/>
          <site name="laser_site_358" pos="0 0 0" quat="0.710226 0 0.703974 0"/>
          <site name="laser_site_359" pos="0 0 0" quat="0.708689 0 0.705521 0"/>
          <site name="laser_site_360" pos="0 0 0" quat="0.707148 0 0.707066 0"/>
          <site name="laser_site_361" pos="0 0 0" quat="0.705604 0 0.708607 0"/>
          <site name="laser_site_362" pos="0 0 0" quat="0.704056 0 0.710144 0"/>
          <site name="laser_site_363" pos="0 0 0" quat="0.702505 0 0.711678 0"/>
          <site name="laser_site_364" pos="0 0 0" quat="0.700951 0 0.713209 0"/>
          <site name="laser_site_365" pos="0 0 0" quat="0.699394 0 0.714737 0"/>
          <site name="laser_site_366" pos="0 0 0" quat="0.697833 0 0.716261 0"/>
          <site name="laser_site_367" pos="0 0 0" quat="0.696269 0 0.717781 0"/>
          <site name="laser_site_368" pos="0 0 0" quat="0.694701 0 0.719298 0"/>
          <site name="laser_site_369" pos="0 0 0" quat="0.69313 0 0.720812 0"/>
          <site name="laser_site_370" pos="0 0 0" quat="0.691556 0 0.722323 0"/>
          <site name="laser_site_371" pos="0 0 0" quat="0.689979 0 0.72383 0"/>
          <site name="laser_site_372" pos="0 0 0" quat="0.688398 0 0.725333 0"/>
          <site name="laser_site_373" pos="0 0 0" quat="0.686814 0 0.726833 0"/>
          <site name="laser_site_374" pos="0 0 0" quat="0.685227 0 0.72833 0"/>
          <site name="laser_site_375" pos="0 0 0" quat="0.683637 0 0.729823 0"/>
          <site name="laser_site_376" pos="0 0 0" quat="0.682043 0 0.731312 0"/>
          <site name="laser_site_377" pos="0 0 0" quat="0.680446 0 0.732798 0"/>
          <site name="laser_site_378" pos="0 0 0" quat="0.678846 0 0.734281 0"/>
          <site name="laser_site_379" pos="0 0 0" quat="0.677242 0 0.73576 0"/>
          <site name="laser_site_380" pos="0 0 0" quat="0.675635 0 0.737236 0"/>
          <site name="laser_site_381" pos="0 0 0" quat="0.674026 0 0.738708 0"/>
          <site name="laser_site_382" pos="0 0 0" quat="0.672412 0 0.740177 0"/>
          <site name="laser_site_383" pos="0 0 0" quat="0.670796 0 0.741642 0"/>
          <site name="laser_site_384" pos="0 0 0" quat="0.669177 0 0.743103 0"/>
          <site name="laser_site_385" pos="0 0 0" quat="0.667554 0 0.744561 0"/>
          <site name="laser_site_386" pos="0 0 0" quat="0.665928 0 0.746016 0"/>
          <site name="laser_site_387" pos="0 0 0" quat="0.664299 0 0.747467 0"/>
          <site name="laser_site_388" pos="0 0 0" quat="0.662667 0 0.748914 0"/>
          <site name="laser_site_389" pos="0 0 0" quat="0.661032 0 0.750358 0"/>
          <site name="laser_site_390" pos="0 0 0" quat="0.659393 0 0.751798 0"/>
          <site name="laser_site_391" pos="0 0 0" quat="0.657752 0 0.753235 0"/>
          <site name="laser_site_392" pos="0 0 0" quat="0.656107 0 0.754668 0"/>
          <site name="laser_site_393" pos="0 0 0" quat="0.654459 0 0.756098 0"/>
          <site name="laser_site_394" pos="0 0 0" quat="0.652808 0 0.757523 0"/>
          <site name="laser_site_395" pos="0 0 0" quat="0.651154 0 0.758946 0"/>
          <site name="laser_site_396" pos="0 0 0" quat="0.649497 0 0.760364 0"/>
          <site name="laser_site_397" pos="0 0 0" quat="0.647836 0 0.761779 0"/>
          <site name="laser_site_398" pos="0 0 0" quat="0.646173 0 0.763191 0"/>
          <site name="laser_site_399" pos="0 0 0" quat="0.644507 0 0.764599 0"/>
          <site name="laser_site_400" pos="0 0 0" quat="0.642837 0 0.766003 0"/>
          <site name="laser_site_401" pos="0 0 0" quat="0.641165 0 0.767403 0"/>
          <site name="laser_site_402" pos="0 0 0" quat="0.639489 0 0.7688 0"/>
          <site name="laser_site_403" pos="0 0 0" quat="0.63781 0 0.770194 0"/>
          <site name="laser_site_404" pos="0 0 0" quat="0.636129 0 0.771583 0"/>
          <site name="laser_site_405" pos="0 0 0" quat="0.634444 0 0.772969 0"/>
          <site name="laser_site_406" pos="0 0 0" quat="0.632756 0 0.774351 0"/>
          <site name="laser_site_407" pos="0 0 0" quat="0.631065 0 0.77573 0"/>
          <site name="laser_site_408" pos="0 0 0" quat="0.629372 0 0.777104 0"/>
          <site name="laser_site_409" pos="0 0 0" quat="0.627675 0 0.778476 0"/>
          <site name="laser_site_410" pos="0 0 0" quat="0.625975 0 0.779843 0"/>
          <site name="laser_site_411" pos="0 0 0" quat="0.624272 0 0.781207 0"/>
          <site name="laser_site_412" pos="0 0 0" quat="0.622567 0 0.782567 0"/>
          <site name="laser_site_413" pos="0 0 0" quat="0.620858 0 0.783923 0"/>
          <site name="laser_site_414" pos="0 0 0" quat="0.619146 0 0.785276 0"/>
          <site name="laser_site_415" pos="0 0 0" quat="0.617432 0 0.786624 0"/>
          <site name="laser_site_416" pos="0 0 0" quat="0.615714 0 0.787969 0"/>
          <site name="laser_site_417" pos="0 0 0" quat="0.613994 0 0.789311 0"/>
          <site name="laser_site_418" pos="0 0 0" quat="0.612271 0 0.790648 0"/>
          <site name="laser_site_419" pos="0 0 0" quat="0.610544 0 0.791982 0"/>
          <site name="laser_site_420" pos="0 0 0" quat="0.608815 0 0.793312 0"/>
          <site name="laser_site_421" pos="0 0 0" quat="0.607083 0 0.794638 0"/>
          <site name="laser_site_422" pos="0 0 0" quat="0.605348 0 0.795961 0"/>
          <site name="laser_site_423" pos="0 0 0" quat="0.60361 0 0.797279 0"/>
          <site name="laser_site_424" pos="0 0 0" quat="0.60187 0 0.798594 0"/>
          <site name="laser_site_425" pos="0 0 0" quat="0.600126 0 0.799905 0"/>
          <site name="laser_site_426" pos="0 0 0" quat="0.59838 0 0.801213 0"/>
          <site name="laser_site_427" pos="0 0 0" quat="0.59663 0 0.802516 0"/>
          <site name="laser_site_428" pos="0 0 0" quat="0.594878 0 0.803816 0"/>
          <site name="laser_site_429" pos="0 0 0" quat="0.593123 0 0.805112 0"/>
          <site name="laser_site_430" pos="0 0 0" quat="0.591366 0 0.806404 0"/>
          <site name="laser_site_431" pos="0 0 0" quat="0.589605 0 0.807692 0"/>
          <site name="laser_site_432" pos="0 0 0" quat="0.587842 0 0.808976 0"/>
          <site name="laser_site_433" pos="0 0 0" quat="0.586076 0 0.810256 0"/>
          <site name="laser_site_434" pos="0 0 0" quat="0.584307 0 0.811533 0"/>
          <site name="laser_site_435" pos="0 0 0" quat="0.582535 0 0.812806 0"/>
          <site name="laser_site_436" pos="0 0 0" quat="0.58076 0 0.814075 0"/>
          <site name="laser_site_437" pos="0 0 0" quat="0.578983 0 0.81534 0"/>
          <site name="laser_site_438" pos="0 0 0" quat="0.577203 0 0.816601 0"/>
          <site name="laser_site_439" pos="0 0 0" quat="0.57542 0 0.817858 0"/>
          <site name="laser_site_440" pos="0 0 0" quat="0.573635 0 0.819111 0"/>
          <site name="laser_site_441" pos="0 0 0" quat="0.571846 0 0.820361 0"/>
          <site name="laser_site_442" pos="0 0 0" quat="0.570055 0 0.821606 0"/>
          <site name="laser_site_443" pos="0 0 0" quat="0.568262 0 0.822848 0"/>
          <site name="laser_site_444" pos="0 0 0" quat="0.566465 0 0.824086 0"/>
          <site name="laser_site_445" pos="0 0 0" quat="0.564666 0 0.825319 0"/>
          <site name="laser_site_446" pos="0 0 0" quat="0.562864 0 0.826549 0"/>
          <site name="laser_site_447" pos="0 0 0" quat="0.56106 0 0.827775 0"/>
          <site name="laser_site_448" pos="0 0 0" quat="0.559253 0 0.828997 0"/>
          <site name="laser_site_449" pos="0 0 0" quat="0.557443 0 0.830215 0"/>
          <site name="laser_site_450" pos="0 0 0" quat="0.555631 0 0.831429 0"/>
          <site name="laser_site_451" pos="0 0 0" quat="0.553816 0 0.832639 0"/>
          <site name="laser_site_452" pos="0 0 0" quat="0.551998 0 0.833846 0"/>
          <site name="laser_site_453" pos="0 0 0" quat="0.550178 0 0.835048 0"/>
          <site name="laser_site_454" pos="0 0 0" quat="0.548355 0 0.836246 0"/>
          <site name="laser_site_455" pos="0 0 0" quat="0.546529 0 0.83744 0"/>
          <site name="laser_site_456" pos="0 0 0" quat="0.544701 0 0.83863 0"/>
          <site name="laser_site_457" pos="0 0 0" quat="0.54287 0 0.839817 0"/>
          <site name="laser_site_458" pos="0 0 0" quat="0.541037 0 0.840999 0"/>
          <site name="laser_site_459" pos="0 0 0" quat="0.539201 0 0.842177 0"/>
          <site name="laser_site_460" pos="0 0 0" quat="0.537362 0 0.843352 0"/>
          <site name="laser_site_461" pos="0 0 0" quat="0.535521 0 0.844522 0"/>
          <site name="laser_site_462" pos="0 0 0" quat="0.533678 0 0.845688 0"/>
          <site name="laser_site_463" pos="0 0 0" quat="0.531832 0 0.84685 0"/>
          <site name="laser_site_464" pos="0 0 0" quat="0.529983 0 0.848008 0"/>
          <site name="laser_site_465" pos="0 0 0" quat="0.528132 0 0.849163 0"/>
          <site name="laser_site_466" pos="0 0 0" quat="0.526278 0 0.850313 0"/>
          <site name="laser_site_467" pos="0 0 0" quat="0.524422 0 0.851459 0"/>
          <site name="laser_site_468" pos="0 0 0" quat="0.522563 0 0.852601 0"/>
          <site name="laser_site_469" pos="0 0 0" quat="0.520702 0 0.853739 0"/>
          <site name="laser_site_470" pos="0 0 0" quat="0.518838 0 0.854872 0"/>
          <site name="laser_site_471" pos="0 0 0" quat="0.516972 0 0.856002 0"/>
          <site name="laser_site_472" pos="0 0 0" quat="0.515103 0 0.857128 0"/>
          <site name="laser_site_473" pos="0 0 0" quat="0.513232 0 0.85825 0"/>
          <site name="laser_site_474" pos="0 0 0" quat="0.511359 0 0.859367 0"/>
          <site name="laser_site_475" pos="0 0 0" quat="0.509483 0 0.860481 0"/>
          <site name="laser_site_476" pos="0 0 0" quat="0.507605 0 0.86159 0"/>
          <site name="laser_site_477" pos="0 0 0" quat="0.505724 0 0.862695 0"/>
          <site name="laser_site_478" pos="0 0 0" quat="0.503841 0 0.863797 0"/>
          <site name="laser_site_479" pos="0 0 0" quat="0.501955 0 0.864894 0"/>
          <site name="laser_site_480" pos="0 0 0" quat="0.500067 0 0.865987 0"/>
          <site name="laser_site_481" pos="0 0 0" quat="0.498177 0 0.867075 0"/>
          <site name="laser_site_482" pos="0 0 0" quat="0.496284 0 0.86816 0"/>
          <site name="laser_site_483" pos="0 0 0" quat="0.494389 0 0.869241 0"/>
          <site name="laser_site_484" pos="0 0 0" quat="0.492492 0 0.870317 0"/>
          <site name="laser_site_485" pos="0 0 0" quat="0.490592 0 0.871389 0"/>
          <site name="laser_site_486" pos="0 0 0" quat="0.48869 0 0.872458 0"/>
          <site name="laser_site_487" pos="0 0 0" quat="0.486785 0 0.873522 0"/>
          <site name="laser_site_488" pos="0 0 0" quat="0.484879 0 0.874581 0"/>
          <site name="laser_site_489" pos="0 0 0" quat="0.48297 0 0.875637 0"/>
          <site name="laser_site_490" pos="0 0 0" quat="0.481058 0 0.876689 0"/>
          <site name="laser_site_491" pos="0 0 0" quat="0.479145 0 0.877736 0"/>
          <site name="laser_site_492" pos="0 0 0" quat="0.477229 0 0.878779 0"/>
          <site name="laser_site_493" pos="0 0 0" quat="0.47531 0 0.879818 0"/>
          <site name="laser_site_494" pos="0 0 0" quat="0.47339 0 0.880853 0"/>
          <site name="laser_site_495" pos="0 0 0" quat="0.471467 0 0.881884 0"/>
          <site name="laser_site_496" pos="0 0 0" quat="0.469542 0 0.88291 0"/>
          <site name="laser_site_497" pos="0 0 0" quat="0.467615 0 0.883932 0"/>
          <site name="laser_site_498" pos="0 0 0" quat="0.465686 0 0.88495 0"/>
          <site name="laser_site_499" pos="0 0 0" quat="0.463754 0 0.885964 0"/>
          <site name="laser_site_500" pos="0 0 0" quat="0.46182 0 0.886974 0"/>
          <site name="laser_site_501" pos="0 0 0" quat="0.459884 0 0.887979 0"/>
          <site name="laser_site_502" pos="0 0 0" quat="0.457946 0 0.88898 0"/>
          <site name="laser_site_503" pos="0 0 0" quat="0.456006 0 0.889977 0"/>
          <site name="laser_site_504" pos="0 0 0" quat="0.454063 0 0.89097 0"/>
          <site name="laser_site_505" pos="0 0 0" quat="0.452118 0 0.891958 0"/>
          <site name="laser_site_506" pos="0 0 0" quat="0.450171 0 0.892942 0"/>
          <site name="laser_site_507" pos="0 0 0" quat="0.448222 0 0.893922 0"/>
          <site name="laser_site_508" pos="0 0 0" quat="0.446271 0 0.894898 0"/>
          <site name="laser_site_509" pos="0 0 0" quat="0.444318 0 0.895869 0"/>
          <site name="laser_site_510" pos="0 0 0" quat="0.442363 0 0.896836 0"/>
          <site name="laser_site_511" pos="0 0 0" quat="0.440405 0 0.897799 0"/>
          <site name="laser_site_512" pos="0 0 0" quat="0.438445 0 0.898758 0"/>
          <site name="laser_site_513" pos="0 0 0" quat="0.436484 0 0.899712 0"/>
          <site name="laser_site_514" pos="0 0 0" quat="0.43452 0 0.900662 0"/>
          <site name="laser_site_515" pos="0 0 0" quat="0.432554 0 0.901608 0"/>
          <site name="laser_site_516" pos="0 0 0" quat="0.430586 0 0.902549 0"/>
          <site name="laser_site_517" pos="0 0 0" quat="0.428616 0 0.903487 0"/>
          <site name="laser_site_518" pos="0 0 0" quat="0.426644 0 0.904419 0"/>
          <site name="laser_site_519" pos="0 0 0" quat="0.42467 0 0.905348 0"/>
          <site name="laser_site_520" pos="0 0 0" quat="0.422694 0 0.906272 0"/>
          <site name="laser_site_521" pos="0 0 0" quat="0.420716 0 0.907192 0"/>
          <site name="laser_site_522" pos="0 0 0" quat="0.418736 0 0.908108 0"/>
          <site name="laser_site_523" pos="0 0 0" quat="0.416754 0 0.909019 0"/>
          <site name="laser_site_524" pos="0 0 0" quat="0.41477 0 0.909926 0"/>
          <site name="laser_site_525" pos="0 0 0" quat="0.412784 0 0.910829 0"/>
          <site name="laser_site_526" pos="0 0 0" quat="0.410796 0 0.911727 0"/>
          <site name="laser_site_527" pos="0 0 0" quat="0.408806 0 0.912621 0"/>
          <site name="laser_site_528" pos="0 0 0" quat="0.406815 0 0.913511 0"/>
          <site name="laser_site_529" pos="0 0 0" quat="0.404821 0 0.914396 0"/>
          <site name="laser_site_530" pos="0 0 0" quat="0.402825 0 0.915277 0"/>
          <site name="laser_site_531" pos="0 0 0" quat="0.400827 0 0.916154 0"/>
          <site name="laser_site_532" pos="0 0 0" quat="0.398828 0 0.917026 0"/>
          <site name="laser_site_533" pos="0 0 0" quat="0.396826 0 0.917894 0"/>
          <site name="laser_site_534" pos="0 0 0" quat="0.394823 0 0.918757 0"/>
          <site name="laser_site_535" pos="0 0 0" quat="0.392818 0 0.919616 0"/>
          <site name="laser_site_536" pos="0 0 0" quat="0.390811 0 0.920471 0"/>
          <site name="laser_site_537" pos="0 0 0" quat="0.388802 0 0.921321 0"/>
          <site name="laser_site_538" pos="0 0 0" quat="0.386791 0 0.922167 0"/>
          <site name="laser_site_539" pos="0 0 0" quat="0.384778 0 0.923009 0"/>
          <site name="laser_site_540" pos="0 0 0" quat="0.382764 0 0.923846 0"/>
          <site name="laser_site_541" pos="0 0 0" quat="0.380748 0 0.924679 0"/>
          <site name="laser_site_542" pos="0 0 0" quat="0.37873 0 0.925507 0"/>
          <site name="laser_site_543" pos="0 0 0" quat="0.37671 0 0.926331 0"/>
          <site name="laser_site_544" pos="0 0 0" quat="0.374688 0 0.927151 0"/>
          <site name="laser_site_545" pos="0 0 0" quat="0.372665 0 0.927966 0"/>
          <site name="laser_site_546" pos="0 0 0" quat="0.370639 0 0.928777 0"/>
          <site name="laser_site_547" pos="0 0 0" quat="0.368612 0 0.929583 0"/>
          <site name="laser_site_548" pos="0 0 0" quat="0.366584 0 0.930385 0"/>
          <site name="laser_site_549" pos="0 0 0" quat="0.364553 0 0.931183 0"/>
          <site name="laser_site_550" pos="0 0 0" quat="0.362521 0 0.931976 0"/>
          <site name="laser_site_551" pos="0 0 0" quat="0.360487 0 0.932764 0"/>
          <site name="laser_site_552" pos="0 0 0" quat="0.358451 0 0.933548 0"/>
          <site name="laser_site_553" pos="0 0 0" quat="0.356414 0 0.934328 0"/>
          <site name="laser_site_554" pos="0 0 0" quat="0.354375 0 0.935103 0"/>
          <site name="laser_site_555" pos="0 0 0" quat="0.352334 0 0.935874 0"/>
          <site name="laser_site_556" pos="0 0 0" quat="0.350292 0 0.936641 0"/>
          <site name="laser_site_557" pos="0 0 0" quat="0.348247 0 0.937403 0"/>
          <site name="laser_site_558" pos="0 0 0" quat="0.346202 0 0.93816 0"/>
          <site name="laser_site_559" pos="0 0 0" quat="0.344154 0 0.938913 0"/>
          <site name="laser_site_560" pos="0 0 0" quat="0.342105 0 0.939662 0"/>
          <site name="laser_site_561" pos="0 0 0" quat="0.340054 0 0.940406 0"/>
          <site name="laser_site_562" pos="0 0 0" quat="0.338002 0 0.941145 0"/>
          <site name="laser_site_563" pos="0 0 0" quat="0.335948 0 0.94188 0"/>
          <site name="laser_site_564" pos="0 0 0" quat="0.333893 0 0.942611 0"/>
          <site name="laser_site_565" pos="0 0 0" quat="0.331836 0 0.943337 0"/>
          <site name="laser_site_566" pos="0 0 0" quat="0.329777 0 0.944059 0"/>
          <site name="laser_site_567" pos="0 0 0" quat="0.327717 0 0.944776 0"/>
          <site name="laser_site_568" pos="0 0 0" quat="0.325655 0 0.945489 0"/>
          <site name="laser_site_569" pos="0 0 0" quat="0.323592 0 0.946197 0"/>
          <site name="laser_site_570" pos="0 0 0" quat="0.321527 0 0.946901 0"/>
          <site name="laser_site_571" pos="0 0 0" quat="0.31946 0 0.9476 0"/>
          <site name="laser_site_572" pos="0 0 0" quat="0.317392 0 0.948294 0"/>
          <site name="laser_site_573" pos="0 0 0" quat="0.315323 0 0.948984 0"/>
          <site name="laser_site_574" pos="0 0 0" quat="0.313252 0 0.94967 0"/>
          <site name="laser_site_575" pos="0 0 0" quat="0.311179 0 0.950351 0"/>
          <site name="laser_site_576" pos="0 0 0" quat="0.309105 0 0.951028 0"/>
          <site name="laser_site_577" pos="0 0 0" quat="0.30703 0 0.9517 0"/>
          <site name="laser_site_578" pos="0 0 0" quat="0.304953 0 0.952367 0"/>
          <site name="laser_site_579" pos="0 0 0" quat="0.302875 0 0.95303 0"/>
          <site name="laser_site_580" pos="0 0 0" quat="0.300795 0 0.953689 0"/>
          <site name="laser_site_581" pos="0 0 0" quat="0.298714 0 0.954343 0"/>
          <site name="laser_site_582" pos="0 0 0" quat="0.296631 0 0.954992 0"/>
          <site name="laser_site_583" pos="0 0 0" quat="0.294547 0 0.955637 0"/>
          <site name="laser_site_584" pos="0 0 0" quat="0.292462 0 0.956277 0"/>
          <site name="laser_site_585" pos="0 0 0" quat="0.290375 0 0.956913 0"/>
          <site name="laser_site_586" pos="0 0 0" quat="0.288287 0 0.957544 0"/>
          <site name="laser_site_587" pos="0 0 0" quat="0.286197 0 0.958171 0"/>
          <site name="laser_site_588" pos="0 0 0" quat="0.284106 0 0.958793 0"/>
          <site name="laser_site_589" pos="0 0 0" quat="0.282014 0 0.95941 0"/>
          <site name="laser_site_590" pos="0 0 0" quat="0.279921 0 0.960023 0"/>
          <site name="laser_site_591" pos="0 0 0" quat="0.277826 0 0.960632 0"/>
          <site name="laser_site_592" pos="0 0 0" quat="0.275729 0 0.961235 0"/>
          <site name="laser_site_593" pos="0 0 0" quat="0.273632 0 0.961835 0"/>
          <site name="laser_site_594" pos="0 0 0" quat="0.271533 0 0.962429 0"/>
          <site name="laser_site_595" pos="0 0 0" quat="0.269433 0 0.963019 0"/>
          <site name="laser_site_596" pos="0 0 0" quat="0.267331 0 0.963605 0"/>
          <site name="laser_site_597" pos="0 0 0" quat="0.265228 0 0.964186 0"/>
          <site name="laser_site_598" pos="0 0 0" quat="0.263124 0 0.964762 0"/>
          <site name="laser_site_599" pos="0 0 0" quat="0.261019 0 0.965334 0"/>
          <site name="laser_site_600" pos="0 0 0" quat="0.258913 0 0.965901 0"/>
          <site name="laser_site_601" pos="0 0 0" quat="0.256805 0 0.966463 0"/>
          <site name="laser_site_602" pos="0 0 0" quat="0.254696 0 0.967021 0"/>
          <site name="laser_site_603" pos="0 0 0" quat="0.252586 0 0.967574 0"/>
          <site name="laser_site_604" pos="0 0 0" quat="0.250474 0 0.968123 0"/>
          <site name="laser_site_605" pos="0 0 0" quat="0.248362 0 0.968667 0"/>
          <site name="laser_site_606" pos="0 0 0" quat="0.246248 0 0.969207 0"/>
          <site name="laser_site_607" pos="0 0 0" quat="0.244133 0 0.969742 0"/>
          <site name="laser_site_608" pos="0 0 0" quat="0.242017 0 0.970272 0"/>
          <site name="laser_site_609" pos="0 0 0" quat="0.2399 0 0.970798 0"/>
          <site name="laser_site_610" pos="0 0 0" quat="0.237782 0 0.971319 0"/>
          <site name="laser_site_611" pos="0 0 0" quat="0.235662 0 0.971835 0"/>
          <site name="laser_site_612" pos="0 0 0" quat="0.233542 0 0.972347 0"/>
          <site name="laser_site_613" pos="0 0 0" quat="0.23142 0 0.972854 0"/>
          <site name="laser_site_614" pos="0 0 0" quat="0.229297 0 0.973357 0"/>
          <site name="laser_site_615" pos="0 0 0" quat="0.227173 0 0.973854 0"/>
          <site name="laser_site_616" pos="0 0 0" quat="0.225048 0 0.974348 0"/>
          <site name="laser_site_617" pos="0 0 0" quat="0.222922 0 0.974836 0"/>
          <site name="laser_site_618" pos="0 0 0" quat="0.220795 0 0.97532 0"/>
          <site name="laser_site_619" pos="0 0 0" quat="0.218667 0 0.9758 0"/>
          <site name="laser_site_620" pos="0 0 0" quat="0.216537 0 0.976274 0"/>
          <site name="laser_site_621" pos="0 0 0" quat="0.214407 0 0.976744 0"/>
          <site name="laser_site_622" pos="0 0 0" quat="0.212276 0 0.97721 0"/>
          <site name="laser_site_623" pos="0 0 0" quat="0.210144 0 0.977671 0"/>
          <site name="laser_site_624" pos="0 0 0" quat="0.20801 0 0.978127 0"/>
          <site name="laser_site_625" pos="0 0 0" quat="0.205876 0 0.978578 0"/>
          <site name="laser_site_626" pos="0 0 0" quat="0.203741 0 0.979025 0"/>
          <site name="laser_site_627" pos="0 0 0" quat="0.201605 0 0.979467 0"/>
          <site name="laser_site_628" pos="0 0 0" quat="0.199467 0 0.979904 0"/>
          <site name="laser_site_629" pos="0 0 0" quat="0.197329 0 0.980337 0"/>
          <site name="laser_site_630" pos="0 0 0" quat="0.19519 0 0.980765 0"/>
          <site name="laser_site_631" pos="0 0 0" quat="0.19305 0 0.981189 0"/>
          <site name="laser_site_632" pos="0 0 0" quat="0.190909 0 0.981608 0"/>
          <site name="laser_site_633" pos="0 0 0" quat="0.188767 0 0.982022 0"/>
          <site name="laser_site_634" pos="0 0 0" quat="0.186625 0 0.982431 0"/>
          <site name="laser_site_635" pos="0 0 0" quat="0.184481 0 0.982836 0"/>
          <site name="laser_site_636" pos="0 0 0" quat="0.182337 0 0.983236 0"/>
          <site name="laser_site_637" pos="0 0 0" quat="0.180191 0 0.983632 0"/>
          <site name="laser_site_638" pos="0 0 0" quat="0.178045 0 0.984022 0"/>
          <site name="laser_site_639" pos="0 0 0" quat="0.175898 0 0.984408 0"/>
          <site name="laser_site_640" pos="0 0 0" quat="0.17375 0 0.98479 0"/>
          <site name="laser_site_641" pos="0 0 0" quat="0.171601 0 0.985166 0"/>
          <site name="laser_site_642" pos="0 0 0" quat="0.169452 0 0.985538 0"/>
          <site name="laser_site_643" pos="0 0 0" quat="0.167301 0 0.985906 0"/>
          <site name="laser_site_644" pos="0 0 0" quat="0.16515 0 0.986268 0"/>
          <site name="laser_site_645" pos="0 0 0" quat="0.162998 0 0.986626 0"/>
          <site name="laser_site_646" pos="0 0 0" quat="0.160846 0 0.98698 0"/>
          <site name="laser_site_647" pos="0 0 0" quat="0.158692 0 0.987328 0"/>
          <site name="laser_site_648" pos="0 0 0" quat="0.156538 0 0.987672 0"/>
          <site name="laser_site_649" pos="0 0 0" quat="0.154383 0 0.988011 0"/>
          <site name="laser_site_650" pos="0 0 0" quat="0.152227 0 0.988346 0"/>
          <site name="laser_site_651" pos="0 0 0" quat="0.150071 0 0.988675 0"/>
          <site name="laser_site_652" pos="0 0 0" quat="0.147914 0 0.989 0"/>
          <site name="laser_site_653" pos="0 0 0" quat="0.145756 0 0.989321 0"/>
          <site name="laser_site_654" pos="0 0 0" quat="0.143597 0 0.989636 0"/>
          <site name="laser_site_655" pos="0 0 0" quat="0.141438 0 0.989947 0"/>
          <site name="laser_site_656" pos="0 0 0" quat="0.139278 0 0.990253 0"/>
          <site name="laser_site_657" pos="0 0 0" quat="0.137117 0 0.990555 0"/>
          <site name="laser_site_658" pos="0 0 0" quat="0.134956 0 0.990852 0"/>
          <site name="laser_site_659" pos="0 0 0" quat="0.132794 0 0.991144 0"/>
          <site name="laser_site_660" pos="0 0 0" quat="0.130632 0 0.991431 0"/>
          <site name="laser_site_661" pos="0 0 0" quat="0.128469 0 0.991714 0"/>
          <site name="laser_site_662" pos="0 0 0" quat="0.126305 0 0.991991 0"/>
          <site name="laser_site_663" pos="0 0 0" quat="0.124141 0 0.992265 0"/>
          <site name="laser_site_664" pos="0 0 0" quat="0.121976 0 0.992533 0"/>
          <site name="laser_site_665" pos="0 0 0" quat="0.11981 0 0.992797 0"/>
          <site name="laser_site_666" pos="0 0 0" quat="0.117644 0 0.993056 0"/>
          <site name="laser_site_667" pos="0 0 0" quat="0.115478 0 0.99331 0"/>
          <site name="laser_site_668" pos="0 0 0" quat="0.11331 0 0.99356 0"/>
          <site name="laser_site_669" pos="0 0 0" quat="0.111143 0 0.993804 0"/>
          <site name="laser_site_670" pos="0 0 0" quat="0.108974 0 0.994045 0"/>
          <site name="laser_site_671" pos="0 0 0" quat="0.106806 0 0.99428 0"/>
          <site name="laser_site_672" pos="0 0 0" quat="0.104636 0 0.994511 0"/>
          <site name="laser_site_673" pos="0 0 0" quat="0.102467 0 0.994736 0"/>
          <site name="laser_site_674" pos="0 0 0" quat="0.100296 0 0.994958 0"/>
          <site name="laser_site_675" pos="0 0 0" quat="0.0981257 0 0.995174 0"/>
          <site name="laser_site_676" pos="0 0 0" quat="0.0959545 0 0.995386 0"/>
          <site name="laser_site_677" pos="0 0 0" quat="0.0937828 0 0.995593 0"/>
          <site name="laser_site_678" pos="0 0 0" quat="0.0916107 0 0.995795 0"/>
          <site name="laser_site_679" pos="0 0 0" quat="0.0894382 0 0.995992 0"/>
          <site name="laser_site_680" pos="0 0 0" quat="0.0872652 0 0.996185 0"/>
          <site name="laser_site_681" pos="0 0 0" quat="0.0850918 0 0.996373 0"/>
          <site name="laser_site_682" pos="0 0 0" quat="0.082918 0 0.996556 0"/>
          <site name="laser_site_683" pos="0 0 0" quat="0.0807438 0 0.996735 0"/>
          <site name="laser_site_684" pos="0 0 0" quat="0.0785693 0 0.996909 0"/>
          <site name="laser_site_685" pos="0 0 0" quat="0.0763943 0 0.997078 0"/>
          <site name="laser_site_686" pos="0 0 0" quat="0.074219 0 0.997242 0"/>
          <site name="laser_site_687" pos="0 0 0" quat="0.0720434 0 0.997402 0"/>
          <site name="laser_site_688" pos="0 0 0" quat="0.0698674 0 0.997556 0"/>
          <site name="laser_site_689" pos="0 0 0" quat="0.067691 0 0.997706 0"/>
          <site name="laser_site_690" pos="0 0 0" quat="0.0655144 0 0.997852 0"/>
          <site name="laser_site_691" pos="0 0 0" quat="0.0633374 0 0.997992 0"/>
          <site name="laser_site_692" pos="0 0 0" quat="0.0611601 0 0.998128 0"/>
          <site name="laser_site_693" pos="0 0 0" quat="0.0589826 0 0.998259 0"/>
          <site name="laser_site_694" pos="0 0 0" quat="0.0568047 0 0.998385 0"/>
          <site name="laser_site_695" pos="0 0 0" quat="0.0546266 0 0.998507 0"/>
          <site name="laser_site_696" pos="0 0 0" quat="0.0524483 0 0.998624 0"/>
          <site name="laser_site_697" pos="0 0 0" quat="0.0502696 0 0.998736 0"/>
          <site name="laser_site_698" pos="0 0 0" quat="0.0480908 0 0.998843 0"/>
          <site name="laser_site_699" pos="0 0 0" quat="0.0459117 0 0.998946 0"/>
          <site name="laser_site_700" pos="0 0 0" quat="0.0437324 0 0.999043 0"/>
          <site name="laser_site_701" pos="0 0 0" quat="0.0415529 0 0.999136 0"/>
          <site name="laser_site_702" pos="0 0 0" quat="0.0393731 0 0.999225 0"/>
          <site name="laser_site_703" pos="0 0 0" quat="0.0371932 0 0.999308 0"/>
          <site name="laser_site_704" pos="0 0 0" quat="0.0350132 0 0.999387 0"/>
          <site name="laser_site_705" pos="0 0 0" quat="0.0328329 0 0.999461 0"/>
          <site name="laser_site_706" pos="0 0 0" quat="0.0306525 0 0.99953 0"/>
          <site name="laser_site_707" pos="0 0 0" quat="0.028472 0 0.999595 0"/>
          <site name="laser_site_708" pos="0 0 0" quat="0.0262913 0 0.999654 0"/>
          <site name="laser_site_709" pos="0 0 0" quat="0.0241105 0 0.999709 0"/>
          <site name="laser_site_710" pos="0 0 0" quat="0.0219296 0 0.99976 0"/>
          <site name="laser_site_711" pos="0 0 0" quat="0.0197485 0 0.999805 0"/>
          <site name="laser_site_712" pos="0 0 0" quat="0.0175674 0 0.999846 0"/>
          <site name="laser_site_713" pos="0 0 0" quat="0.0153862 0 0.999882 0"/>
          <site name="laser_site_714" pos="0 0 0" quat="0.0132049 0 0.999913 0"/>
          <site name="laser_site_715" pos="0 0 0" quat="0.0110236 0 0.999939 0"/>
          <site name="laser_site_716" pos="0 0 0" quat="0.00884221 0 0.999961 0"/>
          <site name="laser_site_717" pos="0 0 0" quat="0.00666078 0 0.999978 0"/>
          <site name="laser_site_718" pos="0 0 0" quat="0.00447931 0 0.99999 0"/>
          <site name="laser_site_719" pos="0 0 0" quat="0.00229782 0 0.999997 0"/>
          <site name="laser_site_720" pos="0 0 0" quat="0.000116327 0 1 0"/>
        </body>
      </body>
      <geom pos="0 0 0.0985" material="white" mesh="base"/>
      <geom pos="0.202 0 0.0945" material="gray10" mesh="sick_tim551"/>
      <geom pos="-0.183 0.183 0.2715" quat="0.382683 0 0 0.92388" material="gray10" mesh="srf05"/>
      <geom pos="-0.259 0 0.2715" quat="0 0 0 1" material="gray10" mesh="srf05"/>
      <geom pos="-0.183 -0.183 0.2715" quat="-0.382683 0 0 0.92388" material="gray10" mesh="srf05"/>
      <geom pos="-0.201 0.1062 0.2935" material="black" mesh="antenna"/>
      <geom pos="-0.201 -0.1062 0.2935" material="black" mesh="antenna"/>
      <geom pos="-0.062 0 0.2915" material="mercury" mesh="torso_fix"/>
      <geom size="0.09 0.1 0.275" pos="-0.062 0 0.5685" type="box" material="gray10"/>
      <geom pos="0 0 0.13" material="orange" mesh="base_ring"/>
      <inertial pos="-0.01 -0.002 0.131" mass="47.112" diaginertia="2.074 2.245 0.897"/>
      <body name="wheel_right_link" pos="0 -0.2022 0.0985" quat="1 -1 0 0">
        <inertial pos="0.0 0.0 0.0" mass="4.4" diaginertia="0.014 0.014 0.027"/>
        <joint name="wheel_right_joint" actuatorfrcrange="-100 100"/>
        <geom material="gray10" mesh="wheel"/>
      </body>
      <body name="wheel_left_link" pos="0 0.2022 0.0985" quat="1 -1 0 0">
        <inertial pos="0.0 0.0 0.0" mass="4.4" diaginertia="0.014 0.014 0.027"/>
        <joint name="wheel_left_joint" actuatorfrcrange="-100 100"/>
        <geom quat="0 -1 0 0" material="gray10" mesh="wheel"/>
      </body>
      <body name="caster_front_right_1_link" pos="0.1695 -0.102 0.065" childclass="wheel">
        <inertial pos="-0.00634599 5.347e-05 -0.0203752" quat="0.966491 -0.00340536 -0.256544 -0.00828025"
          mass="0.0514476" diaginertia="1.66556e-05 1.30896e-05 1.04548e-05"/>
        <joint name="caster_front_right_1_joint" damping="0.5"/>
        <geom material="gray70" mesh="caster_1"/>
        <body name="caster_front_right_2_link" pos="-0.016 0 -0.04" quat="1 -1 0 0">
          <inertial pos="0 0 0" quat="1 0 0 1" mass="0.0885578" diaginertia="1.541e-05 1.075e-05 1.075e-05"/>
          <joint name="caster_front_right_2_joint"/>
          <geom material="gray10" mesh="caster_2"/>
        </body>
      </body>
      <body name="caster_front_left_1_link" pos="0.1695 0.102 0.065" childclass="wheel">
        <inertial pos="-0.00634599 5.347e-05 -0.0203752" quat="0.966491 -0.00340536 -0.256544 -0.00828025"
          mass="0.0514476" diaginertia="1.66556e-05 1.30896e-05 1.04548e-05"/>
        <joint name="caster_front_left_1_joint" damping="0.5"/>
        <geom material="gray70" mesh="caster_1"/>
        <body name="caster_front_left_2_link" pos="-0.016 0 -0.04" quat="1 -1 0 0">
          <inertial pos="0 0 0" quat="1 0 0 1" mass="0.0885578" diaginertia="1.541e-05 1.075e-05 1.075e-05"/>
          <joint name="caster_front_left_2_joint"/>
          <geom material="gray10" mesh="caster_2"/>
        </body>
      </body>
      <body name="caster_back_right_1_link" pos="-0.1735 -0.102 0.065" childclass="wheel">
        <inertial pos="-0.00634599 5.347e-05 -0.0203752" quat="0.966491 -0.00340536 -0.256544 -0.00828025"
          mass="0.0514476" diaginertia="1.66556e-05 1.30896e-05 1.04548e-05"/>
        <joint name="caster_back_right_1_joint" damping="0.5"/>
        <geom material="gray70" mesh="caster_1"/>
        <body name="caster_back_right_2_link" pos="-0.016 0 -0.04" quat="1 -1 0 0">
          <inertial pos="0 0 0" quat="1 0 0 1" mass="0.0885578" diaginertia="1.541e-05 1.075e-05 1.075e-05"/>
          <joint name="caster_back_right_2_joint"/>
          <geom material="gray10" mesh="caster_2"/>
        </body>
      </body>
      <body name="caster_back_left_1_link" pos="-0.1735 0.102 0.065" childclass="wheel">
        <inertial pos="-0.00634599 5.347e-05 -0.0203752" quat="0.966491 -0.00340536 -0.256544 -0.00828025"
          mass="0.0514476" diaginertia="1.66556e-05 1.30896e-05 1.04548e-05"/>
        <joint name="caster_back_left_1_joint" damping="0.5"/>
        <geom material="gray70" mesh="caster_1"/>
        <body name="caster_back_left_2_link" pos="-0.016 0 -0.04" quat="1 -1 0 0">
          <inertial pos="0 0 0" quat="1 0 0 1" mass="0.0885578" diaginertia="1.541e-05 1.075e-05 1.075e-05"/>
          <joint name="caster_back_left_2_joint"/>
          <geom material="gray10" mesh="caster_2"/>
        </body>
      </body>
      <body name="torso_lift_link" pos="-0.062 0 0.8885">
        <inertial pos="0.031711 -0.001004 -0.187315" mass="6.281737" diaginertia="0.230972 0.235034 0.080705"/>
        <joint name="torso_lift_joint" type="slide" range="0 0.35" actuatorfrcrange="-500 500" damping="2000"/>
        <geom material="white" mesh="torso_lift_with_arm"/>
        <body name="head_1_link" pos="0.182 0 0">
          <inertial pos="-0.00508 0.00237 0.07229" mass="0.6222" diaginertia="0.00140223 0.00121968 0.000861083"/>
          <joint name="head_1_joint" range="-1.309 1.309" actuatorfrcrange="-5.197 5.197" damping="0.5"/>
          <geom material="white" mesh="head_1"/>
          <body name="head_2_link" pos="0.005 0 0.098" quat="1 1 0 0">
            <inertial pos="0.0558274 0.0609987 1.58542e-05" mass="0.88693" diaginertia="0.00554181 0.00436261 0.00347586"/>
            <joint name="head_2_joint" range="-1.0472 0.785398" actuatorfrcrange="-5.197 5.197" damping="0.5"/>
            <geom material="white" mesh="head_2"/>
            <camera name="head_camera" pos="0.0908 0.08 0.0" mode="fixed" euler="0 -1.57 0"
                            fovy="45.5" resolution="640 480"/>
          </body>
        </body>
        <body name="arm_1_link" pos="0.15505 0.014 -0.151" quat="1 0 0 -1" childclass="arm">
          <inertial pos="0.061191 -0.022397 -0.012835" mass="1.56343" diaginertia="0.00510233 0.00510233 0.00510233"/>
          <joint name="arm_1_joint" range="0 2.74889" actuatorfrcrange="-43 43" damping="10"/>
          <geom material="white" mesh="arm_1"/>
          <body name="arm_2_link" pos="0.125 0.0195 -0.031" quat="1 1 0 0">
            <inertial pos="0.030432 0.000229 -0.005942" mass="1.8004" diaginertia="0.00437229 0.00432701 0.0017837"/>
            <joint name="arm_2_joint" range="-1.5708 1.09083" actuatorfrcrange="-43 43" damping="10"/>
            <geom material="gray10" mesh="arm_2"/>
            <body name="arm_3_link" pos="0.0895 0 -0.0015" quat="0.5 -0.5 -0.5 0.5">
              <inertial pos="0.007418 -0.004361 -0.134194" mass="1.8" diaginertia="0.0200771 0.0196154 0.00264853"/>
              <joint name="arm_3_joint" range="-3.53429 1.5708" actuatorfrcrange="-26 26" damping="10"/>
              <geom material="gray10" mesh="arm_3"/>
              <body name="arm_4_link" pos="-0.02 -0.027 -0.222" quat="0.5 -0.5 -0.5 -0.5">
                <inertial pos="-0.095658 0.014666 0.018133" mass="1.4327" diaginertia="0.002040 0.008424 0.008686"/>
                <joint name="arm_4_joint" range="-0.392699 2.35619" actuatorfrcrange="-26 26" damping="10"/>
                <geom material="gray10" mesh="arm_4"/>
                <body name="arm_5_link" pos="-0.162 0.02 0.027" quat="1 0 -1 0">
                  <inertial pos="0.001078 -0.000151 -0.077173" mass="0.935914" diaginertia="0.00103619 0.000794527 0.000439824"/>
                  <joint name="arm_5_joint" range="-2.0944 2.0944" actuatorfrcrange="-3 3" damping="1"/>
                  <geom material="mercury" mesh="arm_5-wrist-2017"/>
                  <body name="arm_6_link" pos="0 0 0.15" quat="0.5 -0.5 -0.5 -0.5">
                    <inertial pos="-0.000153 -0.003122 0.000183" mass="0.302758" diaginertia="3.85419e-05 3.33205e-05 3.29226e-05"/>
                    <joint name="arm_6_joint" range="-1.41372 1.41372" actuatorfrcrange="-6.6 6.6" damping="1"/>
                    <geom material="mercury" mesh="arm_6-wrist-2017"/>
                    <body name="arm_7_link" quat="0.5 0.5 0.5 0.5">
                      <inertial pos="-0.000173894 0.000176395 0.0817355" mass="1.00276" diaginertia="0.0025841 0.0022568 0.000746434"/>
                      <joint name="arm_7_joint" range="-2.0944 2.0944"  actuatorfrcrange="-6.6 6.6" damping="1"/>
                      <geom size="0.005 0.0025" pos="0 0 0.047" quat="-1 0 0 1" type="cylinder" material="mercury"/>
                      <geom size="0.0225 0.00785" pos="0 0 0.05385" quat="-1 0 0 0" type="cylinder" material="mercury"/>
                      <geom size="0.025 0.004875" pos="0 0 0.066575" quat="-1 0 0 1" type="cylinder" material="gray10"/>
                      <geom pos="0 0 0.076575" quat="0 -1 1 0" material="white" mesh="gripper_link"/>
                      <body name="gripper_right_finger_link" pos="0 0 0.076575" quat="0 -1 1 0">
                        <inertial pos="0.008658 0.019724 -0.149125" mass="0.107001" diaginertia="0.000242 0.000236 0.000018"/>
                        <joint name="gripper_right_finger_joint" axis="1 0 0" type="slide" range="0 0.045" damping="80" frictionloss="1.0"/>
                        <geom quat="4.63268e-05 0 0 1" material="black" mesh="gripper_right_finger_link"/>
                      </body>
                      <body name="gripper_left_finger_link" pos="0 0 0.076575" quat="0 -1 1 0">
                        <inertial pos="-0.008658 -0.019724 -0.149125" mass="0.107001" diaginertia="0.000242 0.000236 0.000018"/>
                        <joint name="gripper_left_finger_joint" axis="-1 0 0" type="slide" range="0 0.045" damping="80" frictionloss="1.0"/>
                        <geom quat="4.63268e-05 0 0 1" material="black" mesh="gripper_left_finger_link"/>
                      </body>
                    </body>
                  </body>
                </body>
              </body>
            </body>
          </body>
        </body>
      </body>
    </body>
  </worldbody>

  <!-- Added collision exclude to avoid unwanted contact forces between robot bodies -->
  <contact>
    <exclude body1="arm_2_link" body2="torso_lift_link"/>
    <exclude body1="arm_3_link" body2="torso_lift_link"/>
    <exclude body1="gripper_right_finger_link" body2="gripper_left_finger_link"/>
  </contact>

  <include file="laser_180_sensors.xml" />


</mujoco>
